Workbook
Name __SW1: INDIRECT(CHOOSE(#REF!,"NEOR2","NEOPLUSI","NEOPLUSII","ERPX2","ERPXP","ICUBE"))
Name _80486SX_25: [3]COST!#REF!
Name _L80486SX_25: [3]COST!#REF!
Name _SW1: INDIRECT(CHOOSE(#REF!,"NEOR2","NEOPLUSI","NEOPLUSII","ERPX2","ERPXP","ICUBE"))
Name _SX25: [3]COST!#REF!
Name \a: #N/A
Name \b: #N/A
Name \p: #N/A
Name \z: #N/A
Name a: #REF!
Name a: #REF!
Name aaaaa: #REF!
Name aaaaa: #REF!
Name C80486DX_33: [3]COST!#REF!
Name C80486DX_50: [3]COST!#REF!
Name C80486DX2_50: [3]COST!#REF!
Name C80486DX2_66: [3]COST!#REF!
Name C80486SX_25: [3]COST!#REF!
Name C80486SX_33: [3]COST!#REF!
Name Chart_1: "Chart 1"
Name DATA1: #N/A
Name DATA2: #N/A
Name ECMM: #REF!
Name ECMM: #REF!
Name EC등급: #REF!
Name EC등급: #REF!
Name ERP영업센터: [6]담당자!#REF!
Name FACTOR1: 3.64
Name FACTOR2: 0.5363
Name FACTOR3: 0.963
Name FACTOR4: 3.576
Name FACTOR5: 0.95
Name FACTOR6: 0.9
Name FACTOR7: (1-0.3*2/3)/1.215/1.1
Name L80486SX_25: [3]COST!#REF!
Name LDASKJDH: #REF!
Name LDASKJDH: #REF!
Name MKTMM: #REF!
Name MKTMM: #REF!
Name MKT등급: #REF!
Name MKT등급: #REF!
Name MONTH: #N/A
Name PRICE: [3]COST!#REF!
Name QR: #REF!
Name QR: #REF!
Name US: [3]COST!$P$2
Name 기본단가: #REF!
Name 기본단가: #REF!
Name 기준등급: #REF!
Name 기준등급: #REF!
Name ㅂㅈㄷ: #REF!
Name ㅂㅈㄷ: #REF!
Name 영업2부_EBP영업1팀: [6]담당자!#REF!
Name 영업2부_EBP영업2팀: [6]담당자!#REF!
Name 영업2부_EBP영업3팀: [6]담당자!#REF!
Name 영업2부_EBP영업4팀: [6]담당자!#REF!
Name 영업2부_위하고영업1팀: [6]담당자!#REF!
Name 영업2부_위하고영업2팀: [6]담당자!#REF!
Name 영업3부_EBP영업1팀: [6]담당자!#REF!
Name 영업3부_EBP영업2팀: [6]담당자!#REF!

Sheet 표지
B25: =TODAY() -> 46097

Sheet Amaranth 10 Cloud 견적서
B5: 업체명 | I5: 견적일자 | J5: =TODAY() -> 46097
B6: 담당자 | G6: (귀중) | I6: 제안사 | J6: 134-81-08473 (주)더존비즈온 / 강원도 춘천시 남산면 버들1길 130 대표이사 김 용 우 (직인생략)
B7: 견적명 | D7: Amaranth 10 Cloud 견적
B8: 견적번호 | D8: =CONCATENATE("Douzone-A10C-Ver1.0-",TEXT(J5,"YYYYMMDD")) -> Douzone-A10C-Ver1.0-20260316 | I8: 영업센터 | J8: 솔루션영업본부 솔루션영업 0Unit
B9: 견적담당 | D9: 홍길동 과장 (010 - 0000 - 0000) | I9: 영업담당 | J9: 홍길동 과장 (010 - 0000 - 0000)
B11: 하기와 같이 견적합니다. (부가세 별도)
B12: 라이선스 | D12: ="금 "&NUMBERSTRING((N110),1)&TEXT((N110),"원 정 (\ #,###")& "원 : VAT 별도)" -> 금 영원 정 (₩ 원 : VAT 별도) | I12: 납품기일 | J12: 별도 협의 후 결정
B13: 교육비 | D13: ="금 "&NUMBERSTRING(($N$117),1)&TEXT(($N$117),"원 정 (\ #,###")& "원 : VAT 별도)" -> 금 영원 정 (₩ 원 : VAT 별도) | I13: 서비스장소 | J13: 더존 D-Cloud 센터
B14: 연사용료 (연납) | D14: ="금 "&NUMBERSTRING(($N$143),1)&TEXT(($N$143),"원 정 (\ #,###")& "원 : VAT 별도)" -> 금 영원 정 (₩ 원 : VAT 별도) | I14: 지불조건 | J14: 하기 비고사항 참조
B15: 월사용료 (월납) | D15: ="금 "&NUMBERSTRING(($N$140),1)&TEXT(($N$140),"원 정 (\ #,###")& "원 : VAT 별도)" -> 금 영원 정 (₩ 원 : VAT 별도) | I15: 유효기간 | J15: 견적일로부터 30일
B16: ONE AI 사용료 (연납) | D16: ="금 "&NUMBERSTRING(($N$147),1)&TEXT(($N$147),"원 정 (\ #,###")& "원 : VAT 별도)" -> 금 영원 정 (₩ 원 : VAT 별도)
B17: 외부 옵션 | D17: ="금 "&NUMBERSTRING(($N$155),1)&TEXT(($N$155),"원 정 (\ #,###")& "원 : VAT 별도)" -> 금 영원 정 (₩ 원 : VAT 별도)
B18: 1) 연사용료 (연납) : SSL인증서 및 연말 정산 유저 사용료
B19: [ 1. 라이선스 / 모듈 ] | O19: [ 단위 : 원, 부가세 별도 ]
B20: 구분 | C20: 항목 | F20: 사양 | I20: 단가 | J20: 수량 | K20: 단위 | L20: 표준금액 | M20: D/C | N20: 금액 | O20: 비 고 | S20: 할인 불가 여부 | T20: 발주 시 참고 사항
B21: EBP | C21: Enterprise Business Platform (EBP) | E21: 기본엔진 | F21: ERP 모듈 도입시 전자결재, 일정, 원피스, 원챔버 파일저장 기능 제공 법인 1개 기본 제공 (UC 회사 추가도 하나의 법인에 해당) | I21: 조건부무상 | J21: 0 | K21: 식 | L21: 조건부무상 | N21: 조건부무상 | T21: - 무상 제공이여도 발주 필수
E22: 법인추가 | F22: 1개 법인 추가당 | I22: 1000000 | J22: 0 | K22: 식 | L22: =IF(J22="","",I22*J22) -> 0 | N22: =IF(J22="","",TRUNC((L22*(1-M22)),-1)) -> 0
E23: 양식제작 | F23: HTML 양식제작 | I23: 100000 | J23: 0 | K23: 식 | L23: =IF(J23="","",I23*J23) -> 0 | N23: =IF(J23="","",TRUNC((L23*(1-M23)),-1)) -> 0
B24: 언어 | C24: 다국어팩 | F24: 영어, 중국어, 일본어 제공 | I24: 5000000 | J24: 0 | K24: 식 | L24: =IF(J24="","",I24*J24) -> 0 | N24: =IF(J24="","",TRUNC((L24*(1-M24)),-1)) -> 0 | O24: - 한국어 외 영어, 중국어, 일본어를 팩 형태로 제공
B25: 회계 모듈 | C25: 기본 | E25: 회계관리 | F25: 지출결의/경비관리, 자동전표처리(스크랩핑 관리), 전표/장부관리, 자금관리, 결산/재무제표관리,사용자정의재무제표관리,부가가치세관리,고정자산관리,법인세관리,업무용승용차관리 [임직원 업무관리] 경비청구, 업무용승용차관리, 지출결의/경비관리/계산서 | I25: 10000000 | J25: 0 | K25: 식 | L25: =IF(J25="","",I25*J25) -> 0 | N25: =IF(J25="","",TRUNC((L25*(1-M25)),-1)) -> 0 | T25: - 스마트증빙 (법인형) 고객 발주 시 무상 제공이여도 NSM10 등록 필수
C26: 옵션 | E26: 모바일자금관리 | F26: 가용자금 흐름, 자금손익, 자금관리 서비스 | I26: 2000000 | J26: 0 | K26: 식 | L26: =IF(J26="","",I26*J26) -> 0 | N26: =IF(J26="","",TRUNC((L26*(1-M26)),-1)) -> 0 | O26: =IF(AND(J26>0,J55=0),"UC 확장팩 및 모바일 APP서비스 선택 시 견적 가능","")
E27: 그룹 재무 제표 | F27: 그룹 재무제표 (기초정보 / 그룹재무제표) | I27: 2000000 | J27: 0 | K27: 식 | L27: =IF(J27="","",I27*J27) -> 0 | N27: =IF(J27="","",TRUNC((L27*(1-M27)),-1)) -> 0 | O27: - 멀티법인 재무제표 통합 조회
E28: 금융 서비스 연동 | F28: 금융서비스 연동 (기초정보 / 전표,이체처리) | I28: 3000000 | J28: 0 | K28: 식 | L28: =IF(J28="","",I28*J28) -> 0 | N28: =IF(J28="","",TRUNC((L28*(1-M28)),-1)) -> 0 | O28: - 우리, 신한, 농협, 하나, 기업, 국민, 부산, 경남
E29: 자동 전표 처리 | F29: 외부시스템 연동 ( API 및 EXCEL 연동 ) | I29: 4000000 | J29: 0 | K29: 식 | L29: =IF(J29="","",I29*J29) -> 0 | N29: =IF(J29="","",TRUNC((L29*(1-M29)),-1)) -> 0
E30: 스마트증빙 | F30: 기초정보・자료수집, 통장, 전자세금계산서, 카드, 현금영수증 | I30: 조건부무상 | J30: 0 | K30: 식 | L30: 조건부무상 | N30: 조건부무상
B31: 인사 모듈 | C31: 기본 | E31: 인사 관리 | F31: 인사관리, 근태관리, 급여관리, 사회보험관리, 그밖의소득관리, 세무관리, 법정의무교육(별도가입) [임직원 업무관리] 근태신청, 연차촉진계획, 인사정보, 인사발령, 교육관리, 증명서 신청 및 발급 | I31: 7500000 | J31: 0 | K31: 식 | L31: =IF(J31="","",I31*J31) -> 0 | N31: =IF(J31="","",TRUNC((L31*(1-M31)),-1)) -> 0 | O31: - 법정의무교육은 고객사별 서비스 가입 절차 필요
C32: 옵션 | E32: 근태 리더기 연동 | F32: 에스원, 쉴더스, KT텔레캅 | I32: 3000000 | J32: 0 | K32: 식 | L32: =IF(J32="","",I32*J32) -> 0 | N32: =IF(J32="","",TRUNC((L32*(1-M32)),-1)) -> 0
E33: 인사근태 확장형 | F33: 교대근무 시간등록, 월별근무 계획등록, 유연근무시간등록 | I33: 5000000 | J33: 0 | K33: 식 | L33: =IF(J33="","",I33*J33) -> 0 | N33: =IF(J33="","",TRUNC((L33*(1-M33)),-1)) -> 0
E34: 일/주단위 근무시간 정산 | F34: 일단위 소정근로시간 / 주단위 실근로시간 40시간 미만 근로자 근무시간 정산 | I34: 2000000 | J34: 0 | K34: 식 | L34: =IF(J34="","",I34*J34) -> 0 | N34: =IF(J34="","",TRUNC((L34*(1-M34)),-1)) -> 0
E35: 대외활동 관리 | F35: 비영리기관의 외부 강의 등 대외활동 신고관리 | I35: 4000000 | J35: 0 | K35: 식 | L35: =IF(J35="","",I35*J35) -> 0 | N35: =IF(J35="","",TRUNC((L35*(1-M35)),-1)) -> 0
E36: 모바일 ForMe | F36: 모바일 출퇴근, 근무시간관리, 근태관리, 휴가관리, 급여명세서, 증명서관리 ※ 모바일 ForMe에서 제공되는 근태 신청서 : 외근, 출장, 연장근무, 연차휴가, 기타휴가 | I36: 1000000 | J36: 0 | K36: 식 | L36: =IF(J36="","",I36*J36) -> 0 | N36: =IF(J36="","",TRUNC((L36*(1-M36)),-1)) -> 0 | O36: =IF(AND(J36>0,J55=0),"인사 관리, UC 확장팩 및 모바일 APP서비스 선택 시 견적 가능","")
B37: 예산 모듈 | C37: 기본 | E37: 예산 관리 | F37: 예산편성, 예산집행, 예산장부 [임직원 업무관리 활성화] 예산집행관리 | I37: 5500000 | J37: 0 | K37: 식 | L37: =IF(J37="","",I37*J37) -> 0 | N37: =IF(J37="","",TRUNC((L37*(1-M37)),-1)) -> 0 | O37: =IF(AND(J37>0,J25=0),"회계관리 선택 시 견적 가능","")
C38: 옵션 | E38: 출장복명 | F38: 여비지급명세서작성, 여비지급현황 | I38: 1000000 | J38: 0 | K38: 식 | L38: =IF(J38="","",I38*J38) -> 0 | N38: =IF(J38="","",TRUNC((L38*(1-M38)),-1)) -> 0
E39: 교비회계 재무제표관리 | F39: 자금예산서(교비), 추가경정자금예산서(교비) 등 | I39: 1000000 | J39: 0 | K39: 식 | L39: =IF(J39="","",I39*J39) -> 0 | N39: =IF(J39="","",TRUNC((L39*(1-M39)),-1)) -> 0
E40: 산학협력단 재무제표관리 | F40: 산학협력단회계처리규칙을 적용 받는 재무제표 및 부속명세서 예/결산서 8종, 재무제표 부속명세서 22본 제공 | I40: 1000000 | J40: 0 | K40: 식 | L40: =IF(J40="","",I40*J40) -> 0 | N40: =IF(J40="","",TRUNC((L40*(1-M40)),-1)) -> 0
E41: 공익법인예산장부 | F41: 전용계좌개설신고서, 전용계좌외거래명세서 등 | I41: 2000000 | J41: 0 | K41: 식 | L41: =IF(J41="","",I41*J41) -> 0 | N41: =IF(J41="","",TRUNC((L41*(1-M41)),-1)) -> 0
E42: 중소기업 구매목표관리 | F42: 구매목표비율조정, 구매목표비율현황, 기업성격관리 | I42: 2000000 | J42: 0 | K42: 식 | L42: =IF(J42="","",I42*J42) -> 0 | N42: =IF(J42="","",TRUNC((L42*(1-M42)),-1)) -> 0
E43: 예산회계 자율통제관리 | F43: 자율통제시나리오설정, 카드승인모니터링검증 등 | I43: 2000000 | J43: 0 | K43: 식 | L43: =IF(J43="","",I43*J43) -> 0 | N43: =IF(J43="","",TRUNC((L43*(1-M43)),-1)) -> 0
E44: 지방출자출연기관 예산장부 | F44: 수입지출예산명세서 / 예산총괄표 | I44: 2000000 | J44: 0 | K44: 식 | L44: =IF(J44="","",I44*J44) -> 0 | N44: =IF(J44="","",TRUNC((L44*(1-M44)),-1)) -> 0
B45: 자산 모듈 | C45: 기본 | E45: 자산 관리 | F45: 플랜갤러리, 구매관리, 검수관리, 대금지급관리, 자산등록관리, 자산실사관리, 자산기초환경설정, 개인자산실사 | I45: 4000000 | J45: 0 | K45: 식 | L45: =IF(J45="","",I45*J45) -> 0 | N45: =IF(J45="","",TRUNC((L45*(1-M45)),-1)) -> 0 | O45: =IF(AND(J45>0,OR(J25=0,J37=0)),"회계관리, 예산관리 선택 시 견적 가능","")
...

Sheet 교육비
A1: 구분 | B1: 항목 | E1: 사양 | G1: 금액 | I1: 비고
G2: FoEX 교육 | H2: 방문 교육 (설치형 / Cloud형 동일)
A3: ERP | B3: "회계, 예산, 인사" 공통 필수 교육비 | E3: 기초세팅 교육 : 2회 | G3: 1000000 | H3: 2000000
B4: 회계 | D4: 회계관리 교육비 | E4: 관리자 교육 : 2회 | G4: 1000000 | H4: 2000000
B5: 예산 | D5: 예산관리 교육비 (영리) | E5: 기초세팅 교육 : 1회 | G5: 500000 | H5: 1000000
D6: 예산관리 교육비 (비영리) | E6: 기초세팅 교육 : 1회, 관리자 교육 : 1회 / 총 2회 | G6: 1000000 | H6: 2000000
B7: 자산 | D7: 자산관리 교육비 | E7: 기초세팅 교육 : 1회 | G7: 500000 | H7: 1000000
B8: 인사 | D8: 인사관리 교육비 | E8: 관리자 교육 : 2회 | G8: 1000000 | H8: 2000000
D9: 인사근태확장형 교육비 | E9: 기초세팅 추가 교육 : 2회 | G9: 1000000 | H9: 2000000
B10: "물류" 공통 필수 교육비 | E10: 기초세팅 교육 : 2회 | G10: 1000000 | H10: 2000000 | I10: - "물류+생산" 동시 도입시 기초세팅 교육 4회에서 3회로 조정 (FoEX 교육 : 150만원 / 방문 교육 : 300만원)
B11: 물류 | D11: 영업관리 교육비 | E11: 관리자 교육 : 2회 | G11: 1000000 | H11: 2000000 | I11: - 수출 제외
D12: 구매관리 교육비 | E12: 관리자 교육 : 2회 | G12: 1000000 | H12: 2000000 | I12: - 수입 제외
D13: 수출 교육비 | E13: 관리자 교육 : 1회 | G13: 500000 | H13: 1000000
D14: 수입 교육비 | E14: 관리자 교육 : 1회 | G14: 500000 | H14: 1000000
D15: 모바일 물류관리 교육비 | E15: 기초세팅 교육 : 1회, 관리자 교육 : 1회 / 총 2회 | G15: - | H15: 2000000 | I15: - 터치인터페이스 및 바코드 장비 연동시 FoEX 교육 불가 (방문 교육만 가능)
D16: 온라인 쇼핑몰 교육비 | E16: 관리자 교육 : 1회 | G16: 500000 | H16: 1000000 | I16: - API 연동시 FoEX 교육 불가 (방문 교육만 가능)
B17: "생산" 공통 필수 교육비 | E17: 기초세팅 교육 : 2회 | G17: 1000000 | H17: 2000000 | I17: - "물류+생산" 동시 도입시 기초세팅 교육 4회에서 3회로 조정 (FoEX 교육 : 150만원 / 방문 교육 : 300만원)
B18: 생산 | D18: 생산관리 교육비 | E18: 관리자 교육 : 2회 | G18: 1000000 | H18: 2000000
D19: 외주관리 교육비 | E19: 관리자 교육 : 1회 | G19: 500000 | H19: 1000000
D20: 원가관리 교육비 | E20: 관리자 교육 : 1회 | G20: 500000 | H20: 1000000
A21: UC | B21: 리걸테크 에디션 | D21: 단독 교육비 | E21: 기초세팅교육 : 2회, 관리자 교육 : 2회 / 총 4회 ※ ERP 및 UC확장팩 모듈 구매 없는 단독 사용 기준 | G21: 2000000 | H21: 4000000
D22: 교육비 | E22: 관리자 교육 : 2회 | G22: 1000000 | H22: 2000000
B23: UC 확장팩 | D23: 영리 교육비 | E23: 기초세팅 교육 : 1회, 관리자 교육 : 1회 / 총 2회 | G23: 1000000 | H23: 2000000
D24: 비영리 교육비 | E24: 기초세팅 교육 : 2회, 관리자 교육 : 2회 / 총 4회 | G24: 2000000 | H24: 4000000
B25: UC 단독팩 교육비 | E25: 기초세팅 교육 : 2회, 관리자 교육 : 2회 / 총 4회 | G25: - | H25: 4000000
B26: CRM 교육비 | E26: 기초세팅 교육 : 1회, 관리자 교육 : 1회, 사용자 교육 1회 / 총 3회 | G26: - | H26: 3000000 | I26: - CRM FoEX 교육(유상) 1:1 교육만 가능 (교육 쿠폰 사용 불가)
A27: 추가 교육 | B27: ONE AI 교육비 (2회) | E27: ONE AI 구축교육 2회 | G27: 1000000 | H27: 2000000 | I27: - 선택 교육
B28: ONE AI 교육비 (1회) | E28: ONE AI 구축교육 1회 | G28: 500000 | H28: 1000000
B29: 추가 교육비 | E29: 추가 교육 (방문 1회 4시간 기준) | G29: 500000 | H29: 1000000
A30: SET 교육비 | B30: 회계/인사 교육비 (관리모듈 기본 SET) | E30: 기초세팅 교육 4회, 관리자 교육 2회 (회계 1회, 인사 1회) / 총 6회 | G30: 3000000 | H30: 6000000
B31: 회계/인사/UC 확장팩 교육비 (관리모듈 확장 SET) | E31: [영리형 기준]기초세팅 교육 5회, 관리자 교육 3회 (회계 1회, 인사 1회, UC확장팩 1회) / 총 8회 | G31: 4000000 | H31: 8000000
B32: 영업/구매 교육비 (물류/유통 기본 SET) | E32: 기초세팅 교육 3회, 관리자 교육 3회 (영업 1회, 구매 1회, 물류공통 1회) / 총 6회 | G32: 3000000 | H32: 6000000 | I32: - 수출/수입 포함시 관리자 교육 각 1회씩 추가 (FoEX 교육 : 50만원 / 방문 교육 : 100만원)
B33: 영업/구매/UC 확장팩 교육비 (물류/유통 확장 SET) | E33: [영리형 기준]기초세팅 교육 4회, 관리자 교육 4회 (영업 1회, 구매 1회,물류공통1회, UC 확장팩 1회) / 총 8회 | G33: 4000000 | H33: 8000000 | I33: - 수출/수입 포함시 관리자 교육 각 1회씩 추가 (FoEX 교육 : 50만원 / 방문 교육 : 100만원)
B34: 생산/외주/원가 교육비 (제조/생산 기본 SET) | E34: 기초세팅 교육 3회, 관리자 교육 3회 (생산 2회, 제조통합 1회) / 총 6회 | G34: 3000000 | H34: 6000000
B35: 생산/외주/원가/UC 확장팩 교육비 (제조/생산 확장 SET) | E35: [영리형 기준]기초세팅 교육 4회, 관리자 교육 4회 (생산 2회, 제조통합1회, UC 확장팩 1회) / 총 8회 4,000,000 | G35: 4000000 | H35: 8000000
B36: 영업/구매/생산/외주/원가 교육비 (제조/생산 기본 SET) | E36: 기초세팅 교육 6회, 관리자 교육 5회 (영업 1회, 구매 1회, 생산 2회, 제조통합 1회) / 총 11회 | G36: 5500000 | H36: 11000000 | I36: - 수출/수입 포함시 관리자 교육 각 1회씩 추가 (FoEX 교육 : 50만원 / 방문 교육 : 100만원)
B37: 영업/구매/생산/외주/원가 UC 확장팩 교육비 (제조/생산 확장 SET) | E37: [영리형 기준]기초세팅 교육 7회, 관리자 교육 6회 (영업 1회, 구매 1회, 생산 2회, 제조통합 1회, UC 확장팩 1회) / 총 13회 | G37: 6500000 | H37: 13000000 | I37: - 수출/수입 포함시 관리자 교육 각 1회씩 추가 (FoEX 교육 : 50만원 / 방문 교육 : 100만원)
B38: 회계/인사/영업/구매 교육비 (물류 전모듈 기본 SET) | E38: 기초세팅 교육 7회, 관리자 교육 5회 (회계 1회, 인사 1회, 영업 1회, 구매 1회, 물류공통 1회) / 총 12회 | G38: 6000000 | H38: 12000000 | I38: - 수출/수입 포함시 관리자 교육 각 1회씩 추가 (FoEX 교육 : 50만원 / 방문 교육 : 100만원)
B39: 회계/인사/영업/구매 UC 확장팩 교육비 (물류 전모듈 확장 SET) | E39: [영리형 기준]기초세팅 교육 8회, 관리자 교육 6회 (회계 1회, 인사 1회, 영업 1회, 구매 1회, UC 확장팩 1회, 물류공통 1회) / 총 14회 | G39: 7000000 | H39: 14000000 | I39: - 수출/수입 포함시 관리자 교육 각 1회씩 추가 (FoEX 교육 : 50만원 / 방문 교육 : 100만원)
B40: 회계/인사/영업/구매/생산/외주/ 원가 교육비 (제조 전모듈 기본 SET) | E40: 기초세팅 교육 10회, 관리자 교육 7회 (회계 1회, 인사 1회, 영업 1회, 구매 1회, 생산 2회, 제조공통 1회) / 총 17회 | G40: 8500000 | H40: 17000000 | I40: - 수출/수입 포함시 관리자 교육 각 1회씩 추가 (FoEX 교육 : 50만원 / 방문 교육 : 100만원)
...

Sheet ONE AI
A1: 항목 | C1: 사양 | F1: 단가
A2: Amaranth 10 ONE AI | B2: 25요금제(연납) | C2: 55만 Credit 제공(월) | F2: 3000000
B3: 35요금제(연납) | C3: 77만 Credit 제공(월) | F3: 4200000
B4: 50요금제(연납) | C4: 110만 Credit 제공(월) | F4: 6000000
B5: 75요금제(연납) | C5: 165만 Credit 제공(월) | F5: 9,000,00
B6: 100 요금제(연납) | C6: 220만 Credit 제공(월) | F6: 12000000
B7: 200 요금제(연납) | C7: 440만 Credit 제공(월) | F7: 24000000
B8: 300 요금제(연납) | C8: 660만 Credit 제공(월) | F8: 36000000
B10: 25요금제(월납) | C10: 55만 Credit 제공(월) | F10: 250000
B11: 35요금제(월납) | C11: 77만 Credit 제공(월) | F11: 350000
B12: 50요금제(월납) | C12: 110만 Credit 제공(월) | F12: 500000
B13: 75요금제(월납) | C13: 165만 Credit 제공(월) | F13: 750000
B14: 100 요금제(월납) | C14: 220만 Credit 제공(월) | F14: 1000000
B15: 200 요금제(월납) | C15: 440만 Credit 제공(월) | F15: 2000000
B16: 300 요금제(월납) | C16: 660만 Credit 제공(월) | F16: 3000000

Sheet 마케팅
C2: 대표메일 | D2: 대표메일 10유저 이하 | E2: 무상
D3: 대표메일 10유저-20유저 이하 | E3: 40000
D4: 대표메일 20유저 이상 | E4: 별도협의
C11: 인증서 | D11: 기본 SSL인증서 | E11: 기본 SSL 인증서 SECTIGO Basic WildCard - 한개의 도메인 사용시 적용 - 한개의 도메인을 하나의 기본 SSL인증서로 사용 가능 | F11: 500000
D12: 멀티 SSL인증서 | E12: 멀티 SSL 인증서 SECTIGO Basic WildCard + Single Card - 두개 이상의 도메인 사용시 적용 (최소 발주 수량 2EA) - 두개 이상의 도메인을 하나의 멀티 SSL인증서로 사용 가능 | F12: 700000
C16: 노무관리 | D16: 50유저 이하 | E16: 최대 50명 등록 가능 | F16: 7500
D17: 100유저 이하 | E17: 최대 100명 등록 가능 | F17: 12500
D18: 150유저 이하 | E18: 최대 150명 등록 가능 | F18: 20000
D19: 300유저 이하 | E19: 최대 300명 등록 가능 | F19: 37500
D20: 500유저 이하 | E20: 최대 500명 등록 가능 | F20: 62500
D21: 501유저 이상 | E21: 500명 이상 등록 인원 별도 협의 | F21: 별도협의
D25: 팩스/문자 60만포인트(월 5만 포인트) | E25: 30000
D26: 팩스/문자 120만포인트 | E26: 60000
D27: 팩스/문자 240만포인트 | E27: 120000
D28: 팩스/문자 360만포인트 | E28: 180000
D29: 팩스/문자 600만포인트 | E29: 300000
C35: 전문가 | D35: 1유저-10유저 | E35: 50000
D36: 11유저-50유저 | E36: 40000
D37: 50유저 초과 | E37: 별도협의
C42: 사용자 | D42: 1유저-50유저 | E42: 13000
D43: 51유저-100유저 | E43: 12000
D44: 101유저-200유저 | E44: 11000
D45: 200유저 초과 | E45: 별도협의
C48: 메일 | D48: 1유저-200유저 | E48: 2000
D49: 200유저 초과 | E49: 별도협의
E53: 회계 + UC 기본 교육비총 구축회수 4회 (방문 4회) | F53: 4000000
E54: 인사 + UC 기본 교육비총 구축회수 4회 (방문 4회) | F54: 4000000
E55: 영업 + UC 기본 교육비총 구축회수 4회 (방문 4회) | F55: 4000000
E56: 구매 + UC 기본 교육비총 구축회수 4회 (방문 4회) | F56: 4000000
E57: 생산 + UC 기본 교육비총 구축회수 4회 (방문 4회) | F57: 4000000
E58: 외주관리 교육비총 구축횟수 2회 (방문 2회) | F58: 2000000
E59: 원가관리 교육비총 구축횟수 2회 (방문 2회) | F59: 2000000
E60: 모바일 물류관리 유통 및 제조 교육비총 구축횟수 2회 (방문 2회) | F60: 2000000
E61: 온라인 쇼핑몰 구축/교육비총 구축횟수 1회 (방문 1회) | F61: 1000000
E62: UC 확장팩 교육비총 구축횟수 4회 (방문 4회) | F62: 4000000
E63: UC 단독팩 교육비총 구축횟수 6회 (방문 6회) | F63: 6000000
E64: ERP10 연동 구축비 | F64: 별도협의
D71: FoEX 교육비
D72: DX 교육비
